Workbook

Sheet Instructions
A1: SME Loan Eligibility Checker
A2: BlackRock Private Data Service - Automation Portfolio
A4: Purpose
A5: This add-in validates SME loan portfolios against configurable eligibility criteria
A6: for guarantee programs offered to EU financial intermediaries (banks, pension funds,
A7: insurance companies). It automates what would otherwise be a manual, error-prone process.
A9: How to Use
A10: 1. Enter loan portfolio data in the 'Loan Portfolio' sheet (or use the UserForm to add records)
A11: 2. Review and configure eligibility rules in the 'Eligibility Criteria' sheet
A12: 3. Set FX rates in the 'FX Rates' sheet if loans are in non-EUR currencies
A13: 4. Click 'Run Eligibility Check' from the custom ribbon tab or UserForm
A14: 5. Review results in 'Validation Results' and 'Dashboard' sheets
... A35: Built as: Technical portfolio for BlackRock PDS Automation role

Sheet Loan Portfolio
A1: Loan ID | B1: Borrower Name | C1: Country | D1: Sector | E1: NACE Code | F1: SME Classification | G1: Annual Revenue (Local CCY) | H1: Employees | I1: Loan Amount (Local CCY) | J1: Currency | K1: Loan Amount (EUR) | L1: Interest Rate (%) | M1: Maturity Date | N1: Loan Purpose | O1: Existing Guarantee (%) | P1: Collateral Value (Local CCY) | Q1: Date of Origination | R1: Borrower Tax ID | S1: Status
A2: LN-0001 | B2: Borrower_001 | C2: Germany | D2: Manufacturing | E2: C10 | F2: Micro | G2: 10777801 | H2: 29 | I2: 234805 | J2: EUR | K2: =IF(J2="EUR",I2,I2/VLOOKUP(J2,'FX Rates'!A:B,2,FALSE())) | L2: 0.0669 | M2: 46704 | N2: Equipment Purchase | O2: 0 | P2: 26868 | Q2: 45984 | R2: GE895285932 | S2: Pending
A3: LN-0002 | B3: Borrower_002 | C3: France | D3: Retail | E3: G47 | F3: Small | G3: 1508591 | H3: 152 | I3: 3564336 | J3: EUR | K3: =IF(J3="EUR",I3,I3/VLOOKUP(J3,'FX Rates'!A:B,2,FALSE())) | L3: 0.0172 | M3: 46394 | N3: Equipment Purchase | O3: 0 | P3: 2119613 | Q3: 45908 | R3: FR128492780 | S3: Pending
A4: LN-0003 | B4: Borrower_003 | C4: Italy | D4: Technology | E4: J62 | F4: Medium | G4: 3385942 | H4: 184 | I4: 6500000 | J4: EUR | K4: =IF(J4="EUR",I4,I4/VLOOKUP(J4,'FX Rates'!A:B,2,FALSE())) | L4: 0.0444 | M4: 47122 | N4: R&D Investment | O4: 0.1 | P4: 3394997 | Q4: 45298 | R4: IT914763202 | S4: Active
A5: LN-0004 | B5: Borrower_004 | C5: Spain | D5: Agriculture | E5: A01 | F5: Medium | G5: 2728638 | H5: 179 | I5: 3570146 | J5: EUR | K5: =IF(J5="EUR",I5,I5/VLOOKUP(J5,'FX Rates'!A:B,2,FALSE())) | L5: 0.0388 | M5: 46521 | N5: Equipment Purchase | O5: 0.1 | P5: 428700 | Q5: 45386 | R5: SP507943839 | S5: Active
A6: LN-0005 | B6: Borrower_005 | C6: Poland | D6: Healthcare | E6: Q86 | F6: Small | G6: 6072674 | H6: 89 | I6: 2243961 | J6: PLN | K6: =IF(J6="EUR",I6,I6/VLOOKUP(J6,'FX Rates'!A:B,2,FALSE())) | L6: 0.0715 | M6: 47697 | N6: Refinancing | O6: 0.3 | P6: 261779 | Q6: 45679 | S6: Pending
A7: LN-0006 | B7: Borrower_006 | C7: Netherlands | D7: Construction | E7: F41 | F7: Small | G7: 4968715 | H7: 161 | I7: 5000 | J7: EUR | K7: =IF(J7="EUR",I7,I7/VLOOKUP(J7,'FX Rates'!A:B,2,FALSE())) | L7: 0.0554 | M7: 47645 | N7: Working Capital | O7: 0 | P7: 955874 | Q7: 45588 | R7: NE185675980 | S7: Active
A8: LN-0007 | B8: Borrower_007 | C8: Czech Republic | D8: Transport | E8: H49 | F8: Micro | G8: 3955582 | H8: 26 | I8: 3213729 | J8: CZK | K8: =IF(J8="EUR",I8,I8/VLOOKUP(J8,'FX Rates'!A:B,2,FALSE())) | L8: 0.0345 | M8: 45680 | N8: Inventory | O8: 0.1 | P8: 682220 | Q8: 45671 | R8: CZ481469012 | S8: Active
A9: LN-0007 | B9: Borrower_008 | C9: Romania | D9: Energy | E9: D35 | F9: Medium | G9: 11293673 | H9: 69 | I9: 623967 | J9: RON | K9: =IF(J9="EUR",I9,I9/VLOOKUP(J9,'FX Rates'!A:B,2,FALSE())) | L9: 0.0576 | M9: 46553 | N9: R&D Investment | O9: 0.5 | P9: 128351 | Q9: 45459 | R9: RO596348124 | S9: Active
A10: LN-0009 | B10: Borrower_009 | C10: Hungary | D10: Services | E10: M69 | F10: Small | G10: 4578972 | H10: 164 | I10: 4697033 | K10: =IF(J10="EUR",I10,I10/VLOOKUP(J10,'FX Rates'!A:B,2,FALSE())) | L10: 0.0304 | M10: 46867 | N10: Inventory | O10: 0 | P10: 960697 | Q10: 45324 | R10: HU964411347 | S10: Active
A11: LN-0010 | B11: Borrower_010 | C11: Portugal | D11: Food & Beverage | E11: C11 | F11: Medium | G11: 75000000 | H11: 69 | I11: 580230 | J11: EUR | K11: =IF(J11="EUR",I11,I11/VLOOKUP(J11,'FX Rates'!A:B,2,FALSE())) | L11: 0.0298 | M11: 47364 | N11: Real Estate | O11: 0.1 | P11: 111477 | Q11: 45963 | R11: PO636045484 | S11: Active
A12: LN-0011 | B12: Borrower_011 | C12: Germany | D12: Manufacturing | E12: C10 | F12: Micro | G12: 14892520 | H12: 165 | I12: 3874128 | J12: EUR | K12: =IF(J12="EUR",I12,I12/VLOOKUP(J12,'FX Rates'!A:B,2,FALSE())) | L12: 0.025 | M12: 46488 | N12: Equipment Purchase | O12: 0.5 | P12: 2354548 | Q12: 45843 | R12: GE382116655 | S12: Defaulted
A13: LN-0012 | B13: Borrower_012 | C13: France | D13: Retail | E13: G47 | F13: Small | G13: 9857725 | H13: 110 | I13: -150000 | J13: EUR | K13: =IF(J13="EUR",I13,I13/VLOOKUP(J13,'FX Rates'!A:B,2,FALSE())) | L13: 0.043 | M13: 46652 | N13: Equipment Purchase | O13: 0.3 | P13: 2069955 | Q13: 45385 | R13: FR911514914 | S13: Active
A14: LN-0013 | B14: Borrower_013 | C14: Italy | D14: Technology | E14: J62 | F14: Medium | G14: 14496909 | H14: 320 | I14: 1307125 | J14: EUR | K14: =IF(J14="EUR",I14,I14/VLOOKUP(J14,'FX Rates'!A:B,2,FALSE())) | L14: 0.0589 | M14: 47596 | N14: Refinancing | O14: 0.3 | P14: 66613 | Q14: 45686 | R14: IT509760584 | S14: Pending
A15: LN-0014 | C15: Spain | D15: Agriculture | E15: A01 | F15: Medium | G15: 7902574 | H15: 136 | I15: 2134014 | J15: EUR | K15: =IF(J15="EUR",I15,I15/VLOOKUP(J15,'FX Rates'!A:B,2,FALSE())) | L15: 0.083 | M15: 46226 | N15: Real Estate | O15: 0.5 | P15: 240232 | Q15: 45990 | R15: SP676567501 | S15: Active
B16: Borrower_015 | C16: Poland | D16: Healthcare | E16: Q86 | F16: Small | G16: 4526583 | H16: 197 | I16: 2878598 | J16: PLN | K16: =IF(J16="EUR",I16,I16/VLOOKUP(J16,'FX Rates'!A:B,2,FALSE())) | L16: 0.0228 | M16: 47093 | N16: Equipment Purchase | O16: 0.2 | P16: 13611 | Q16: 45561 | R16: PO637500247 | S16: Active
A17: LN-0016 | B17: Borrower_016 | C17: Netherlands | D17: Construction | E17: F41 | F17: Small | G17: 3047281 | H17: 130 | I17: 917638 | J17: EUR | K17: =IF(J17="EUR",I17,I17/VLOOKUP(J17,'FX Rates'!A:B,2,FALSE())) | L17: 0.125 | M17: 46814 | N17: Inventory | O17: 0.5 | P17: 532323 | Q17: 45915 | R17: NE313579170 | S17: Active
A18: LN-0017 | B18: Borrower_017 | C18: Czech Republic | D18: Transport | E18: H49 | F18: Micro | G18: 6323233 | H18: 196 | I18: 1380171 | J18: CZK | K18: =IF(J18="EUR",I18,I18/VLOOKUP(J18,'FX Rates'!A:B,2,FALSE())) | L18: 0.0528 | M18: 47797 | N18: R&D Investment | O18: 0 | P18: 679804 | Q18: 45792 | R18: CZ120912992 | S18: Active
A19: LN-0018 | B19: Borrower_018 | C19: Romania | D19: Energy | E19: D35 | F19: Medium | H19: 79 | I19: 2033671 | J19: RON | K19: =IF(J19="EUR",I19,I19/VLOOKUP(J19,'FX Rates'!A:B,2,FALSE())) | L19: 0.0191 | M19: 47364 | N19: Working Capital | O19: 0 | P19: 1534921 | Q19: 45789 | R19: RO976198296 | S19: Active
A20: LN-0019 | B20: Borrower_019 | C20: Hungary | D20: Services | E20: M69 | F20: Small | G20: 12810786 | H20: 137 | I20: 1079955 | J20: HUF | K20: =IF(J20="EUR",I20,I20/VLOOKUP(J20,'FX Rates'!A:B,2,FALSE())) | L20: 0.024 | M20: 47176 | N20: R&D Investment | O20: 0.9 | P20: 277932 | Q20: 45832 | R20: HU751325257 | S20: Active
A21: LN-0020 | B21: Borrower_020 | C21: Portugal | D21: Food & Beverage | E21: C11 | F21: Medium | G21: 3603384 | H21: 139 | I21: TBD | J21: EUR | K21: =IF(J21="EUR",I21,I21/VLOOKUP(J21,'FX Rates'!A:B,2,FALSE())) | L21: 0.0649 | M21: 47020 | N21: Real Estate | O21: 0.5 | P21: 783119 | Q21: 45740 | R21: PO655742829 | S21: Active
A22: LN-0021 | B22: Borrower_021 | C22: Germany | D22: Manufacturing | E22: C10 | F22: Micro | G22: 2080113 | H22: 64 | I22: 1909897 | J22: EUR | K22: =IF(J22="EUR",I22,I22/VLOOKUP(J22,'FX Rates'!A:B,2,FALSE())) | L22: 0.0195 | M22: 46246 | N22: R&D Investment | O22: 0.3 | P22: 482585 | Q22: 45894 | R22: GE336456621 | S22: Active
A23: LN-0022 | B23: Borrower_022 | C23: France | D23: Retail | E23: G47 | F23: Small | G23: 1241066 | H23: N/A | I23: 518868 | J23: EUR | K23: =IF(J23="EUR",I23,I23/VLOOKUP(J23,'FX Rates'!A:B,2,FALSE())) | L23: 0.031 | M23: 46267 | N23: Inventory | O23: 0.1 | P23: 37149 | Q23: 45818 | R23: FR355555531 | S23: Active
A24: LN-0023 | B24: Borrower_023 | C24: Italy | D24: Technology | E24: J62 | F24: Medium | G24: 11273584 | H24: 125 | I24: 1822148 | J24: EUR | K24: =IF(J24="EUR",I24,I24/VLOOKUP(J24,'FX Rates'!A:B,2,FALSE())) | L24: 0.0527 | M24: 47684 | N24: R&D Investment | O24: 0.3 | P24: 991262 | Q24: 45092 | R24: IT942478695 | S24: Active
A25: LN-0024 | B25: Borrower_024 | C25: Spain | D25: Agriculture | E25: A01 | F25: Medium | G25: confidential | H25: 105 | I25: 1622274 | J25: EUR | K25: =IF(J25="EUR",I25,I25/VLOOKUP(J25,'FX Rates'!A:B,2,FALSE())) | L25: 0.0216 | M25: 47552 | N25: Refinancing | O25: 0.1 | P25: 888308 | Q25: 45712 | R25: SP601463916 | S25: Active
A26: LN-0025 | B26: Borrower_025 | C26: Poland | D26: Healthcare | E26: Q86 | F26: Small | G26: 12281863 | H26: 14 | I26: 850588 | J26: PLN | K26: =IF(J26="EUR",I26,I26/VLOOKUP(J26,'FX Rates'!A:B,2,FALSE())) | L26: 0.0192 | M26: not a date | N26: Expansion | O26: 0 | P26: 260735 | Q26: 45488 | R26: PO304235259 | S26: Pending
A27: LN-0026 | B27: Borrower_026 | C27: Netherlands | D27: Construction | E27: F41 | F27: Small | G27: 7576486 | H27: 36 | I27: 3563999 | J27: EUR | K27: =IF(J27="EUR",I27,I27/VLOOKUP(J27,'FX Rates'!A:B,2,FALSE())) | L27: 0.0278 | M27: 47150 | N27: Equipment Purchase | O27: 0 | P27: 1858625 | Q27: 45855 | R27: NE205128697 | S27: Active
A28: LN-0026 | B28: Borrower_027 | C28: Czech Republic | D28: Transport | E28: H49 | F28: Micro | G28: 10991175 | H28: 139 | I28: 148797 | J28: CZK | K28: =IF(J28="EUR",I28,I28/VLOOKUP(J28,'FX Rates'!A:B,2,FALSE())) | L28: 0.0828 | M28: 47746 | N28: Inventory | O28: 0 | P28: 21798 | Q28: 45708 | R28: CZ621453189 | S28: Active
A29: LN-0028 | B29: Borrower_028 | C29: Romania | D29: Energy | E29: D35 | F29: Medium | G29: 3636084 | H29: 103 | I29: 516869 | J29: RON | K29: =IF(J29="EUR",I29,I29/VLOOKUP(J29,'FX Rates'!A:B,2,FALSE())) | L29: 0.0265 | M29: 46207 | N29: Refinancing | O29: 0.1 | P29: 411078 | Q29: pending | R29: RO406284028 | S29: Active
A30: LN-0029 | B30: Borrower_029 | C30: Hungary | D30: Services | E30: M69 | F30: Small | G30: 11736866 | H30: 188 | I30: 4687122 | J30: SGD | K30: =IF(J30="EUR",I30,I30/VLOOKUP(J30,'FX Rates'!A:B,2,FALSE())) | L30: 0.0613 | M30: 47199 | N30: Equipment Purchase | O30: 0 | P30: 1244482 | Q30: 45514 | R30: HU162795957 | S30: Pending
A31: LN-0030 | B31: Borrower_030 | C31: Portugal | D31: Food & Beverage | E31: C11 | F31: Medium | G31: 12393621 | H31: 139 | I31: 536349 | J31: EUR | K31: =IF(J31="EUR",I31,I31/VLOOKUP(J31,'FX Rates'!A:B,2,FALSE())) | L31: 0.0674 | M31: 46320 | N31: Working Capital | O31: 0.3 | P31: 249974 | Q31: 45806 | R31: PO670292350 | S31: Active
A32: LN-0031 | B32: MegaCorp Industries | C32: Germany | D32: Manufacturing | E32: C10 | F32: Medium | G32: 35000000 | H32: 180 | I32: 2000000 | J32: EUR | K32: =IF(J32="EUR",I32,I32/VLOOKUP(J32,'FX Rates'!A:B,2,FALSE())) | L32: 0.045 | M32: 47284 | N32: Expansion | O32: 0 | P32: 500000 | Q32: 45352 | R32: DE100000001 | S32: Active
A33: LN-0032 | B33: MegaCorp Industries | C33: Germany | D33: Manufacturing | E33: C10 | F33: Medium | G33: 35000000 | H33: 180 | I33: 2000000 | J33: EUR | K33: =IF(J33="EUR",I33,I33/VLOOKUP(J33,'FX Rates'!A:B,2,FALSE())) | L33: 0.045 | M33: 47284 | N33: Expansion | O33: 0 | P33: 500000 | Q33: 45352 | R33: DE100000002 | S33: Active
A34: LN-0033 | B34: MegaCorp Industries | C34: Germany | D34: Manufacturing | E34: C10 | F34: Medium | G34: 35000000 | H34: 180 | I34: 2000000 | J34: EUR | K34: =IF(J34="EUR",I34,I34/VLOOKUP(J34,'FX Rates'!A:B,2,FALSE())) | L34: 0.045 | M34: 47284 | N34: Expansion | O34: 0 | P34: 500000 | Q34: 45352 | R34: DE100000003 | S34: Active
A35: LN-0034 | B35: MegaCorp Industries | C35: Germany | D35: Manufacturing | E35: C10 | F35: Medium | G35: 35000000 | H35: 180 | I35: 2000000 | J35: EUR | K35: =IF(J35="EUR",I35,I35/VLOOKUP(J35,'FX Rates'!A:B,2,FALSE())) | L35: 0.045 | M35: 47284 | N35: Expansion | O35: 0 | P35: 500000 | Q35: 45352 | R35: DE100000004 | S35: Active
A36: LN-0035 | B36: TechAlpha GmbH | C36: Germany | D36: Technology | E36: J62 | F36: Small | G36: 8000000 | H36: 80 | I36: 1500000 | J36: EUR | K36: =IF(J36="EUR",I36,I36/VLOOKUP(J36,'FX Rates'!A:B,2,FALSE())) | L36: 0.055 | M36: 46997 | N36: R&D Investment | O36: 0 | P36: 300000 | Q36: 45458 | R36: DE200000001 | S36: Active
A37: LN-0036 | B37: TechBeta SA | C37: France | D37: Technology | E37: J62 | F37: Small | G37: 8000000 | H37: 80 | I37: 1500000 | J37: EUR | K37: =IF(J37="EUR",I37,I37/VLOOKUP(J37,'FX Rates'!A:B,2,FALSE())) | L37: 0.055 | M37: 46997 | N37: R&D Investment | O37: 0 | P37: 300000 | Q37: 45458 | R37: FR200000002 | S37: Active
A38: LN-0037 | B38: TechGamma Sp | C38: Poland | D38: Technology | E38: J62 | F38: Small | G38: 8000000 | H38: 80 | I38: 1500000 | J38: PLN | K38: =IF(J38="EUR",I38,I38/VLOOKUP(J38,'FX Rates'!A:B,2,FALSE())) | L38: 0.055 | M38: 46997 | N38: R&D Investment | O38: 0 | P38: 300000 | Q38: 45458 | R38: PL200000003 | S38: Active
A39: LN-0038 | B39: TechDelta Kft | C39: Hungary | D39: Technology | E39: J62 | F39: Small | G39: 8000000 | H39: 80 | I39: 1500000 | J39: HUF | K39: =IF(J39="EUR",I39,I39/VLOOKUP(J39,'FX Rates'!A:B,2,FALSE())) | L39: 0.055 | M39: 46997 | N39: R&D Investment | O39: 0 | P39: 300000 | Q39: 45458 | R39: HU200000004 | S39: Active
A40: LN-0039 | B40: TechEpsilon BV | C40: Netherlands | D40: Technology | E40: J62 | F40: Small | G40: 8000000 | H40: 80 | I40: 1500000 | J40: EUR | K40: =IF(J40="EUR",I40,I40/VLOOKUP(J40,'FX Rates'!A:B,2,FALSE())) | L40: 0.055 | M40: 46997 | N40: R&D Investment | O40: 0 | P40: 300000 | Q40: 45458 | R40: NL200000005 | S40: Active
...

Sheet Eligibility Criteria
A1: Guarantee Program Configuration
A2: Active Program: | B2: EU SME Guarantee Facility 2025
A4: Criterion | B4: Parameter | C4: Min Value | D4: Max Value | E4: Unit | F4: Notes
A5: Loan Size | B5: Individual loan amount | C5: 10000 | D5: 5000000 | E5: EUR | F5: After FX conversion to EUR
A6: SME Revenue Cap | B6: Annual revenue threshold | D6: 50000000 | E6: EUR | F6: EU SME definition
A7: Employee Count | B7: Maximum headcount | D7: 250 | E7: Persons | F7: EU SME definition
A8: SME Classification | B8: Eligible classifications | E8: List | F8: Micro, Small, Medium
A9: Eligible Countries | B9: EU/EEA member states | E9: List | F9: See Country List below
A10: Eligible Sectors | B10: Permitted NACE sectors | E10: List | F10: Excludes: Gambling, Weapons, Tobacco
A11: Maturity Range | B11: Loan maturity window | C11: 1 | D11: 10 | E11: Years | F11: From origination date
A12: Maximum Interest Rate | B12: Cap on borrowing cost | D12: 10 | E12: % | F12: Annual rate
A13: Existing Guarantee Cap | B13: Max pre-existing guarantee | D13: 80 | E13: % | F13: Of loan amount
A14: Minimum Origination Date | B14: Earliest eligible origination | E14: Date | F14: 01/01/2024
A15: Borrower Status | B15: Loan must be performing | E15: Status | F15: Active only
A18: Eligible Countries | C18: Excluded Sectors
A19: Germany | C19: Gambling & Betting
A20: France | C20: Weapons & Ammunition
A21: Italy | C21: Tobacco Products
A22: Spain
A23: Poland
A24: Netherlands
A25: Czech Republic
A26: Romania
A27: Hungary
A28: Portugal
A32: Concentration Limits
A33: Limit Type | B33: Maximum (%) | C33: Basis | D33: Notes
A34: Single Borrower | B34: 0.05 | C34: Total Portfolio EUR Exposure | D34: No single borrower > 5% of total
A35: Top 10 Borrowers | B35: 0.3 | C35: Total Portfolio EUR Exposure | D35: Combined top 10 < 30%
A36: Single Sector | B36: 0.25 | C36: Total Portfolio EUR Exposure | D36: No single sector > 25%
A37: Single Country | B37: 0.35 | C37: Total Portfolio EUR Exposure | D37: No single country > 35%

Sheet FX Rates
A1: Currency Exchange Rates (per 1 EUR)
A3: Currency | B3: Rate (per EUR) | C3: Last Updated | D3: Source
A4: EUR | B4: 1 | C4: 45992 | D4: Base Currency
A5: PLN | B5: 4.32 | C5: 45992 | D5: ECB Reference Rate
A6: CZK | B6: 25.28 | C6: 45992 | D6: ECB Reference Rate
A7: RON | B7: 4.975 | C7: 45992 | D7: ECB Reference Rate
A8: HUF | B8: 408.5 | C8: 45992 | D8: ECB Reference Rate
A9: GBP | B9: 0.859 | C9: 45992 | D9: ECB Reference Rate
A10: USD | B10: 1.052 | C10: 45992 | D10: ECB Reference Rate
A11: SEK | B11: 11.24 | C11: 45992 | D11: ECB Reference Rate
A12: DKK | B12: 7.459 | C12: 45992 | D12: ECB Reference Rate
A13: CHF | B13: 0.938 | C13: 45992 | D13: ECB Reference Rate

Sheet Data Integrity
A1: Pre-Validation Data Integrity Checks
A2: These checks run before eligibility validation to ensure data quality
A4: Check # | B4: Check Type | C4: Loan ID | D4: Field | E4: Issue | F4: Severity | G4: Action Required
A5: Populated by VBA engine at runtime

Sheet Concentration Analysis
A1: Portfolio Concentration Analysis
A3: Borrower Concentration
A4: Rank | B4: Borrower | C4: EUR Exposure | D4: % of Portfolio | E4: Limit | F4: Status
A5: Populated by VBA engine at runtime
A17: Sector Concentration
A18: Sector | B18: Loan Count | C18: EUR Exposure | D18: % of Portfolio | E18: Limit | F18: Status
A31: Country Concentration
A32: Country | B32: Loan Count | C32: EUR Exposure | D32: % of Portfolio | E32: Limit | F32: Status

Sheet Validation Results
A1: Eligibility Validation Results
A3: Loan ID | B3: Borrower | C3: Country | D3: Loan EUR | E3: Loan Size | F3: Revenue Cap | G3: Employee Limit | H3: Maturity | I3: Interest Rate | J3: Guarantee Cap | K3: Origination Date | L3: Overall Result | M3: Failure Reasons
A4: Populated by VBA engine at runtime

Sheet Dashboard
A1: Eligibility Check Dashboard
A3: Total Loans Submitted | C3: Populated by VBA engine | E3: Ineligible Loans
A5: Eligibility Rate | C5: Total EUR Exposure | E5: Eligible EUR Exposure
A7: Data Integrity Issues | C7: Concentration Breaches | E7: Last Run

Sheet Audit Trail
A1: Eligibility Check Audit Trail
A3: Run # | B3: Timestamp | C3: User | D3: Criteria Set | E3: Records Processed | F3: Eligible | G3: Ineligible | H3: Integrity Issues | I3: Notes
